Workbook

Sheet 1. Bank balance statement
A1: Weekly payments statement.
A2: Prepared by:A.Pallavi Raja
A3: Date: | B3: 45996
A5: S No. | B5: Individual/company/firm | C5: Bank name | D5: Account no. | E5: Book balance | F5: Bank Balance | G5: Last BRS date | H5: Pending task
A6: 1 | B6: Serene Constructions LLP | C6: Yes Bank Ltd | D6: '009763700002308 | E6: ='Summary-Serene LLP'!D23 -> -393541 | F6: 42243 | G6: 05-12-2025
A7: 2 | B7: N Square Biotech Pvt Ltd | C7: ICICI Bank | D7: 112105001906 | E7: ='Summary-NQB'!D21 -> -83098 | F7: 741 | G7: 05-12-2025
A8: 3 | B8: N Square Biotech Pvt Ltd | C8: Kotak Bank | D8: 9614168250 | E8: 6188 | F8: 6188 | G8: 05-12-2025
A9: 4 | B9: Modi Realty Miryalaguda LLP | C9: YES Bank | D9: 009763700001888 | E9: ='Summary-Miriyalaguda LLP'!D20 -> -590656 | F9: 1514 | G9: 05-12-2025
A10: 5 | B10: Modi Realty Miryalaguda LLP | C10: ICICI Bank | D10: 112105001879 | E10: 25000 | F10: 25000 | G10: 05-12-2025
A12: Note: Show balances of all operative and inoprative accounts.
A14: S No. | B14: Individual/company/firm | C14: Bank name | D14: Account no. | E14: FD without lein | F14: FD with Lein | G14: OD limit | H14: OD limit utilised

Sheet Summary-AE
A1: Weekly payments statement.
A2: Company: Alpine Estates | C2: Prepared by: | D2: A.Pallavi Raja
A3: Projecct: | C3: Date: | D3: =('Summary-MRGLLP'!D3) -> 45989
A4: S No. | B4: Weekly payments (include all payments) | C4: Cr balance | D4: Amount | E4: Pay to + VRN/CRN + Desc.
A5: 1 | B5: On a/c.
A6: 2 | B6: Hire charges on a/c.
A7: 3 | B7: Hire charges Dept.
A8: 4 | B8: Job work
A9: 5 | B9: Advance
A10: 6 | B10: Other | D10: =2360+1180 -> 3540 | E10: MPSVC -Accounts Managemnt Services for the month of NOV'25
A11: 7 | B11: Other
A12: 8 | B12: Sub-total A | D12: =SUM(D5:D11) -> 3540
A13: 9 | B13: Item | C13: Last weeks payments made after statement | D13: Payment for current week - Sat to Fri | E13: Remarks
A14: 10 | B14: Cash withdrawals | D14: 0
A15: 11 | B15: Bank/book balance | D15: 1197
A16: 12 | B16: Bank/book balance - sub total A - cash withdrawals | D16: =D15-D14-D12 -> -2343
A17: 13 | B17: Add: OD limit
A18: 14 | B18: Net balance available for payments - Sub-total B | D18: =SUM(D16:D17) -> -2343
A19: 15 | B19: Payments to be made for current week.
A20: 16 | B20: Suppliers bills
A21: 17 | B21: FD - cancel/make
A22: 18 | B22: Other:
A23: 19 | B23: Other:
A24: 20 | B24: Other:
A25: 21 | B25: Other:
A26: 22 | B26: Add: Payments not approved
A27: 23 | B27: Add:
A28: 24 | B28: Sub-total C | D28: =SUM(D20:D25)-D26-D27 -> 0
A29: 25 | B29: Balance: Sub-total B - C
A30: 26 | B30: Pending supplier bills (Subtotal F) | D30: 0
A31: 27 | B31: Payments received during the week. | D31: 0
A32: 28 | B32: Item | D32: Amount | E32: Remarks
A33: 29 | B33: Opening balance last week (Saturday)
A34: 30 | B34: Cash withdrawn during week
A35: 31 | B35: Cash receipts / on a/c reversal
A36: 32 | B36: Subtotal D | D36: =SUM(D33:D35) -> 0
A37: 33 | B37: Cash deposited in bank during week
A38: 34 | B38: Cash expenditure during week
A39: 35 | B39: Sub total E | D39: =SUM(D37:D38) -> 0
A40: 36 | B40: Cash closing balance (Friday) (D - E) | D40: =D36-D39 -> 0
...

Sheet Summary-MRGLLP
A1: Weekly payments statement.
A2: Company: Modi Realty Gagillapur LLP | C2: Prepared by: | D2: A.Pallavi Raja
A3: Projecct: | C3: Date: | D3: 45989
A4: S No. | B4: Weekly payments (include all payments) | C4: Cr balance | D4: Amount | E4: Pay to + VRN/CRN + Desc.
A5: 1 | B5: On a/c.
A6: 2 | B6: Hire charges on a/c.
A7: 3 | B7: Hire charges Dept.
A8: 4 | B8: Job work
A9: 5 | B9: Advance
A10: 6 | B10: Other | D10: =1770+1180 -> 2950 | E10: MPSVC -CA & CS Services for the month of NOV'2025
A11: 7 | B11: Other | D11: 4455 | E11: Shruthi Agarwal Professional fees
A12: 8 | B12: Sub-total A | D12: =SUM(D5:D11) -> 7405
A13: 9 | B13: Item | C13: Last weeks payments made after statement | D13: Payment for current week - Sat to Fri | E13: Remarks
A14: 10 | B14: Cash withdrawals | D14: 0
A15: 11 | B15: Bank/book balance | D15: 3008
A16: 12 | B16: Bank/book balance - sub total A - cash withdrawals | D16: =D15-D14-D12 -> -4397
A17: 13 | B17: Add: OD limit
A18: 14 | B18: Net balance available for payments - Sub-total B | D18: =SUM(D16:D17) -> -4397
A19: 15 | B19: Payments to be made for current week.
A20: 16 | B20: Suppliers bills
A21: 17 | B21: FD - cancel/make
A22: 18 | B22: Other:
A23: 19 | B23: Other:
A24: 20 | B24: Other:
A25: 21 | B25: Other:
A26: 22 | B26: Add: Payments not approved
A27: 23 | B27: Add:
A28: 24 | B28: Sub-total C | D28: =SUM(D20:D25)-D26-D27 -> 0
A29: 25 | B29: Balance: Sub-total B - C
A30: 26 | B30: Pending supplier bills (Subtotal F) | D30: 0
A31: 27 | B31: Payments received during the week. | D31: 0
A32: 28 | B32: Item | D32: Amount | E32: Remarks
A33: 29 | B33: Opening balance last week (Saturday)
A34: 30 | B34: Cash withdrawn during week
A35: 31 | B35: Cash receipts / on a/c reversal
A36: 32 | B36: Subtotal D | D36: =SUM(D33:D35) -> 0
A37: 33 | B37: Cash deposited in bank during week
A38: 34 | B38: Cash expenditure during week
A39: 35 | B39: Sub total E | D39: =SUM(D37:D38) -> 0
A40: 36 | B40: Cash closing balance (Friday) (D - E) | D40: =D36-D39 -> 0
...

Sheet Summary-Siddipet
A1: Weekly payments statement.
A2: Company: Modi Realty Siddipet LLP | C2: Prepared by: | D2: A.Pallavi Raja
A3: Projecct: | C3: Date: | D3: 45989
A4: S No. | B4: Weekly payments (include all payments) | C4: Cr balance | D4: Amount | E4: Pay to + VRN/CRN + Desc.
A5: 1 | B5: On a/c.
A6: 2 | B6: Hire charges on a/c.
A7: 3 | B7: Hire charges Dept.
A8: 4 | B8: Job work
A9: 5 | B9: Advance | D9: 4455 | E9: Shruthi Agarwal Professional fees
A10: 6 | B10: Other | D10: =1770+1180 -> 2950 | E10: MPSVC -CA & CS Services for the month of NOV'25
A11: 7 | B11: Other
A12: 8 | B12: Sub-total A | D12: =SUM(D5:D11) -> 7405
A13: 9 | B13: Item | C13: Last weeks payments made after statement | D13: Payment for current week - Sat to Fri | E13: Remarks
A14: 10 | B14: Cash withdrawals | D14: 0
A15: 11 | B15: Bank/book balance | D15: 3625
A16: 12 | B16: Bank/book balance - sub total A - cash withdrawals | D16: =D15-D14-D12 -> -3780
A17: 13 | B17: Add: OD limit
A18: 14 | B18: Net balance available for payments - Sub-total B | D18: =SUM(D16:D17) -> -3780
A19: 15 | B19: Payments to be made for current week.
A20: 16 | B20: Suppliers bills
A21: 17 | B21: FD - cancel/make
A22: 18 | B22: Other:
A23: 19 | B23: Other:
A24: 20 | B24: Other:
A25: 21 | B25: Other:
A26: 22 | B26: Add: Payments not approved
A27: 23 | B27: Add:
A28: 24 | B28: Sub-total C | D28: =SUM(D20:D25)-D26-D27 -> 0
A29: 25 | B29: Balance: Sub-total B - C
A30: 26 | B30: Pending supplier bills (Subtotal F) | D30: 0
A31: 27 | B31: Payments received during the week. | D31: 0
A32: 28 | B32: Item | D32: Amount | E32: Remarks
A33: 29 | B33: Opening balance last week (Saturday)
A34: 30 | B34: Cash withdrawn during week
A35: 31 | B35: Cash receipts / on a/c reversal
A36: 32 | B36: Subtotal D | D36: =SUM(D33:D35) -> 0
A37: 33 | B37: Cash deposited in bank during week
A38: 34 | B38: Cash expenditure during week
A39: 35 | B39: Sub total E | D39: =SUM(D37:D38) -> 0
A40: 36 | B40: Cash closing balance (Friday) (D - E) | D40: =D36-D39 -> 0
...

Sheet Summary-PMRE
A1: Weekly payments statement.
A2: Company: Paramount Estates | C2: Prepared by: | D2: A.Pallavi raja
A3: Projecct: | C3: Date: | D3: 45989
A4: S No. | B4: Weekly payments (include all payments) | C4: Cr balance | D4: Amount | E4: Pay to + VRN/CRN + Desc.
A5: 1 | B5: On a/c.
A6: 2 | B6: Hire charges on a/c.
A7: 3 | B7: Hire charges Dept.
A8: 4 | B8: Job work
A9: 5 | B9: Advance
A10: 6 | B10: Other | D10: =1180 -> 1180 | E10: MPSVC -Accounts Management ,CA & CS Services for the month of NOV'25
A11: 7 | B11: Sub-total A | D11: =SUM(D5:D10) -> 1180
A12: 8 | B12: Item | C12: Last weeks payments made after statement | D12: Payment for current week - Sat to Fri | E12: Remarks
A13: 9 | B13: Cash withdrawals | D13: 0
A14: 10 | B14: Bank/book balance | D14: 4076
A15: 11 | B15: Bank/book balance - sub total A - cash withdrawals | D15: =D14-D13-D11 -> 2896
A16: 12 | B16: Add: OD limit
A17: 13 | B17: Net balance available for payments - Sub-total B | D17: =SUM(D15:D16) -> 2896
A18: 14 | B18: Payments to be made for current week.
A19: 15 | B19: Suppliers bills
A20: 16 | B20: FD - cancel/make
A21: 17 | B21: Other:
A22: 18 | B22: Other:
A23: 19 | B23: Other:
A24: 20 | B24: Other:
A25: 21 | B25: Add: Payments not approved
A26: 22 | B26: Add:
A27: 23 | B27: Sub-total C | D27: =SUM(D19:D24)-D25-D26 -> 0
A28: 24 | B28: Balance: Sub-total B - C
A29: 25 | B29: Pending supplier bills (Subtotal F) | D29: 0
A30: 26 | B30: Payments received during the week. | D30: 0
A31: 27 | B31: Item | D31: Amount | E31: Remarks
A32: 28 | B32: Opening balance last week (Saturday)
A33: 29 | B33: Cash withdrawn during week
A34: 30 | B34: Cash receipts / on a/c reversal
A35: 31 | B35: Subtotal D | D35: =SUM(D32:D34) -> 0
A36: 32 | B36: Cash deposited in bank during week
A37: 33 | B37: Cash expenditure during week
A38: 34 | B38: Sub total E | D38: =SUM(D36:D37) -> 0
A39: 35 | B39: Cash closing balance (Friday) (D - E) | D39: =D35-D38 -> 0
A40: 36 | B40: Supplier bills statement
...

Sheet Summar-VOC
A1: Weekly payments statement.
A2: Company: Villa Orchids | C2: Prepared by: | D2: A.Pallavi Raja
A3: Projecct: | C3: Date: | D3: 45989
A4: S No. | B4: Weekly payments (include all payments) | C4: Cr balance | D4: Amount | E4: Pay to + VRN/CRN + Desc.
A5: 1 | B5: On a/c.
A6: 2 | B6: Hire charges on a/c.
A7: 3 | B7: Hire charges Dept.
A8: 4 | B8: Job work
A9: 5 | B9: Advance | D9: 4455 | E9: Shruthi Agarwal Professional fees for form-8
A10: 6 | B10: Other | D10: =1770+1180 -> 2950 | E10: MPSVC -CA & CS Services for the month of NOV'25
A11: 7 | B11: Other
A12: 8 | B12: Sub-total A | D12: =SUM(D5:D11) -> 7405
A13: 9 | B13: Item | C13: Last weeks payments made after statement | D13: Payment for current week - Sat to Fri | E13: Remarks
A14: 10 | B14: Cash withdrawals | D14: 0
A15: 11 | B15: Bank/book balance | D15: 9718
A16: 12 | B16: Bank/book balance - sub total A - cash withdrawals | D16: =D15-D14-D12 -> 2313
A17: 13 | B17: Add: OD limit
A18: 14 | B18: Net balance available for payments - Sub-total B | D18: =SUM(D16:D17) -> 2313
A19: 15 | B19: Payments to be made for current week.
A20: 16 | B20: Suppliers bills
A21: 17 | B21: FD - cancel/make
A22: 18 | B22: Other:
A23: 19 | B23: Other:
A24: 20 | B24: Other:
A25: 21 | B25: Other:
A26: 22 | B26: Add: Payments not approved
A27: 23 | B27: Add:
A28: 24 | B28: Sub-total C | D28: =SUM(D20:D25)-D26-D27 -> 0
A29: 25 | B29: Balance: Sub-total B - C
A30: 26 | B30: Pending supplier bills (Subtotal F) | D30: 0
A31: 27 | B31: Payments received during the week. | D31: 0
A32: 28 | B32: Item | D32: Amount | E32: Remarks
A33: 29 | B33: Opening balance last week (Saturday)
A34: 30 | B34: Cash withdrawn during week
A35: 31 | B35: Cash receipts / on a/c reversal
A36: 32 | B36: Subtotal D | D36: =SUM(D33:D35) -> 0
A37: 33 | B37: Cash deposited in bank during week
A38: 34 | B38: Cash expenditure during week
A39: 35 | B39: Sub total E | D39: =SUM(D37:D38) -> 0
A40: 36 | B40: Cash closing balance (Friday) (D - E) | D40: =D36-D39 -> 0
...

Sheet Summary-ESRALLP
A1: Weekly payments statement.
A2: Company: East Side Residency Annoziguda LLP | C2: Prepared by: | D2: A.Pallavi Raja
A3: Projecct: | C3: Date: | D3: 45989
A4: S No. | B4: Weekly payments (include all payments) | C4: Cr balance | D4: Amount | E4: Pay to + VRN/CRN + Desc.
A5: 1 | B5: On a/c.
A6: 2 | B6: Hire charges on a/c.
A7: 3 | B7: Hire charges Dept.
A8: 4 | B8: Job work
A9: 5 | B9: Advance
A10: 6 | B10: Other | D10: =1770+1180 -> 2950 | E10: MPSVC -CA & CS Services for the month of NOV'25
A11: 7 | B11: Other | D11: 4455 | E11: Shruthi Agarwal Professional fees
A12: 8 | B12: Sub-total A | D12: =SUM(D5:D11) -> 7405
A13: 9 | B13: Item | C13: Last weeks payments made after statement | D13: Payment for current week - Sat to Fri | E13: Remarks
A14: 10 | B14: Cash withdrawals | D14: 0
A15: 11 | B15: Bank/book balance | D15: 6641
A16: 12 | B16: Bank/book balance - sub total A - cash withdrawals | D16: =D15-D14-D12 -> -764
A17: 13 | B17: Add: OD limit
A18: 14 | B18: Net balance available for payments - Sub-total B | D18: =SUM(D16:D17) -> -764
A19: 15 | B19: Payments to be made for current week.
A20: 16 | B20: Suppliers bills
A21: 17 | B21: FD - cancel/make
A22: 18 | B22: Other:
A23: 19 | B23: Other:
A24: 20 | B24: Other:
A25: 21 | B25: Other:
A26: 22 | B26: Add: Payments not approved
A27: 23 | B27: Add:
A28: 24 | B28: Sub-total C | D28: =SUM(D20:D25)-D26-D27 -> 0
A29: 25 | B29: Balance: Sub-total B - C
A30: 26 | B30: Pending supplier bills (Subtotal F) | D30: 0
A31: 27 | B31: Payments received during the week. | D31: 0
A32: 28 | B32: Item | D32: Amount | E32: Remarks
A33: 29 | B33: Opening balance last week (Saturday)
A34: 30 | B34: Cash withdrawn during week
A35: 31 | B35: Cash receipts / on a/c reversal
A36: 32 | B36: Subtotal D | D36: =SUM(D33:D35) -> 0
A37: 33 | B37: Cash deposited in bank during week
A38: 34 | B38: Cash expenditure during week
A39: 35 | B39: Sub total E | D39: =SUM(D37:D38) -> 0
A40: 36 | B40: Cash closing balance (Friday) (D - E) | D40: =D36-D39 -> 0
...

Sheet Summary-GWE
A1: Weekly payments statement.
A2: Company: Greenwood Estates | C2: Prepared by: | D2: A.Pallavi Raja
A3: Projecct: | C3: Date: | D3: 45989
A4: S No. | B4: Weekly payments (include all payments) | C4: Cr balance | D4: Amount | E4: Pay to + VRN/CRN + Desc.
A5: 1 | B5: On a/c.
A6: 2 | B6: Hire charges on a/c.
A7: 3 | B7: Hire charges Dept.
A8: 4 | B8: Job work
A9: 5 | B9: Advance
A10: 6 | B10: Other | D10: 1180 | E10: MPSVC -Accounts Management Services for the month of NOV'25
A11: 7 | B11: Sub-total A | D11: =SUM(D5:D10) -> 1180
A12: 8 | B12: Item | C12: Last weeks payments made after statement | D12: Payment for current week - Sat to Fri | E12: Remarks
A13: 9 | B13: Cash withdrawals | D13: 0
A14: 10 | B14: Bank/book balance | D14: 93422
A15: 11 | B15: Bank/book balance - sub total A - cash withdrawals | D15: =D14-D13-D11 -> 92242
A16: 12 | B16: Add: OD limit
A17: 13 | B17: Net balance available for payments - Sub-total B | D17: =SUM(D15:D16) -> 92242
A18: 14 | B18: Payments to be made for current week.
A19: 15 | B19: Suppliers bills
A20: 16 | B20: FD - cancel/make
A21: 17 | B21: Other:
A22: 18 | B22: Other:
A23: 19 | B23: Other:
A24: 20 | B24: Other:
A25: 21 | B25: Add: Payments not approved
A26: 22 | B26: Add:
A27: 23 | B27: Sub-total C | D27: =SUM(D19:D24)-D25-D26 -> 0
A28: 24 | B28: Balance: Sub-total B - C
A29: 25 | B29: Pending supplier bills (Subtotal F) | D29: 0
A30: 26 | B30: Payments received during the week. | D30: 0
A31: 27 | B31: Item | D31: Amount | E31: Remarks
A32: 28 | B32: Opening balance last week (Saturday)
A33: 29 | B33: Cash withdrawn during week
A34: 30 | B34: Cash receipts / on a/c reversal
A35: 31 | B35: Subtotal D | D35: =SUM(D32:D34) -> 0
A36: 32 | B36: Cash deposited in bank during week
A37: 33 | B37: Cash expenditure during week
A38: 34 | B38: Sub total E | D38: =SUM(D36:D37) -> 0
A39: 35 | B39: Cash closing balance (Friday) (D - E) | D39: =D35-D38 -> 0
A40: 36 | B40: Supplier bills statement
...

Sheet Summary-LG Malakpet
A1: Weekly payments statement.
A2: Company:Modi Realty LG Malakpet LLP | C2: Prepared by: | D2: A.Pallavi Raja
A3: Projecct: | C3: Date: | D3: 45989
A4: S No. | B4: Weekly payments (include all payments) | C4: Cr balance | D4: Amount | E4: Pay to + VRN/CRN + Desc.
A5: 1 | B5: On a/c.
A6: 2 | B6: Hire charges on a/c.
A7: 3 | B7: Hire charges Dept.
A8: 4 | B8: Job work
A9: 5 | B9: Advance
A10: 6 | B10: Other | D10: =1770+1770+5900 -> 9440 | E10: MPSVC -Accounts Management ,CA & CS Services for the month of OCT'25
A11: 7 | B11: Other | D11: 300 | E11: ECARD Mallareddy towards colour village map prints
A12: 8 | D12: 10355 | E12: Shruthi Agarwal Professional fees
A13: 9 | B13: Sub-total A | D13: =SUM(D5:D11) -> 9740
A14: 10 | B14: Item | C14: Last weeks payments made after statement | D14: Payment for current week - Sat to Fri | E14: Remarks
A15: 11 | B15: Cash withdrawals | D15: 0
A16: 12 | B16: Bank/book balance | D16: 3321
A17: 13 | B17: Bank/book balance - sub total A - cash withdrawals | D17: =D16-D15-D13 -> -6419
A18: 14 | B18: Add: OD limit
A19: 15 | B19: Net balance available for payments - Sub-total B | D19: =SUM(D17:D18) -> -6419
A20: 16 | B20: Payments to be made for current week.
A21: 17 | B21: Suppliers bills
A22: 18 | B22: FD - cancel/make
A23: 19 | B23: Other:
A24: 20 | B24: Other:
A25: 21 | B25: Other:
A26: 22 | B26: Other:
A27: 23 | B27: Add: Payments not approved
A28: 24 | B28: Add:
A29: 25 | B29: Sub-total C | D29: =SUM(D21:D26)-D27-D28 -> 0
A30: 26 | B30: Balance: Sub-total B - C
A31: 27 | B31: Pending supplier bills (Subtotal F) | D31: 0
A32: 28 | B32: Payments received during the week. | D32: 0
A33: 29 | B33: Item | D33: Amount | E33: Remarks
A34: 30 | B34: Opening balance last week (Saturday)
A35: 31 | B35: Cash withdrawn during week
A36: 32 | B36: Cash receipts / on a/c reversal
A37: 33 | B37: Subtotal D | D37: =SUM(D34:D36) -> 0
A38: 34 | B38: Cash deposited in bank during week
A39: 35 | B39: Cash expenditure during week
A40: 36 | B40: Sub total E | D40: =SUM(D38:D39) -> 0
...

Sheet Summary-CRE
A1: Weekly payments statement.
A2: Company:Modi Realty Creatopolis LLP | C2: Prepared by: | D2: A.Pallavi Raja
A3: Projecct: | C3: Date: | D3: 28-11-2025
A4: S No. | B4: Weekly payments (include all payments) | C4: Cr balance | D4: Amount | E4: Pay to + VRN/CRN + Desc.
A5: 1 | B5: On a/c.
A6: 2 | B6: Hire charges on a/c.
A7: 3 | B7: Hire charges Dept.
A8: 4 | B8: Job work
A9: 5 | B9: Advance
A10: 6 | B10: Other | D10: =1770+1180 -> 2950 | E10: MPSVC -CA & CS Services for the month of NOV'25
A11: 7 | B11: Other | D11: 4455 | E11: Shruthi Agarwal Professional fees
A12: 8 | B12: Sub-total A | D12: =SUM(D5:D11) -> 7405
A13: 9 | B13: Item | C13: Last weeks payments made after statement | D13: Payment for current week - Sat to Fri | E13: Remarks
A14: 10 | B14: Cash withdrawals | D14: 0
A15: 11 | B15: Bank/book balance | D15: 779
A16: 12 | B16: Bank/book balance - sub total A - cash withdrawals | D16: =D15-D14-D12 -> -6626
A17: 13 | B17: Add: OD limit
A18: 14 | B18: Net balance available for payments - Sub-total B | D18: =SUM(D16:D17) -> -6626
A19: 15 | B19: Payments to be made for current week.
A20: 16 | B20: Suppliers bills
A21: 17 | B21: FD - cancel/make
A22: 18 | B22: Other:
A23: 19 | B23: Other:
A24: 20 | B24: Other:
A25: 21 | B25: Other:
A26: 22 | B26: Add: Payments not approved
A27: 23 | B27: Add:
A28: 24 | B28: Sub-total C | D28: =SUM(D20:D25)-D26-D27 -> 0
A29: 25 | B29: Balance: Sub-total B - C
A30: 26 | B30: Pending supplier bills (Subtotal F) | D30: 0
A31: 27 | B31: Payments received during the week. | D31: 0
A32: 28 | B32: Item | D32: Amount | E32: Remarks
A33: 29 | B33: Opening balance last week (Saturday)
A34: 30 | B34: Cash withdrawn during week
A35: 31 | B35: Cash receipts / on a/c reversal
A36: 32 | B36: Subtotal D | D36: =SUM(D33:D35) -> 0
A37: 33 | B37: Cash deposited in bank during week
A38: 34 | B38: Cash expenditure during week
A39: 35 | B39: Sub total E | D39: =SUM(D37:D38) -> 0
A40: 36 | B40: Cash closing balance (Friday) (D - E) | D40: =D36-D39 -> 0
...

Sheet SUMMARY-B&C
A1: Weekly payments statement.
A2: Company:B & C Estates | C2: Prepared by: | D2: A.Pallavi Raja
A3: Projecct: | C3: Date: | D3: 28-11-2025
A4: S No. | B4: Weekly payments (include all payments) | C4: Cr balance | D4: Amount | E4: Pay to + VRN/CRN + Desc.
A5: 1 | B5: On a/c.
A6: 2 | B6: Hire charges on a/c.
A7: 3 | B7: Hire charges Dept.
A8: 4 | B8: Job work
A9: 5 | B9: Advance
A10: 6 | B10: Other | D10: =1180 -> 1180 | E10: MPSVC -CA & CS Services for the month of NOV'25
A11: 7 | B11: Other
A12: 8 | B12: Sub-total A | D12: =SUM(D5:D11) -> 1180
A13: 9 | B13: Item | C13: Last weeks payments made after statement | D13: Payment for current week - Sat to Fri | E13: Remarks
A14: 10 | B14: Cash withdrawals | D14: 0
A15: 11 | B15: Bank/book balance | D15: 76759
A16: 12 | B16: Bank/book balance - sub total A - cash withdrawals | D16: =D15-D14-D12 -> 75579
A17: 13 | B17: Add: OD limit
A18: 14 | B18: Net balance available for payments - Sub-total B | D18: =SUM(D16:D17) -> 75579
A19: 15 | B19: Payments to be made for current week.
A20: 16 | B20: Suppliers bills
A21: 17 | B21: FD - cancel/make
A22: 18 | B22: Other:
A23: 19 | B23: Other:
A24: 20 | B24: Other:
A25: 21 | B25: Other:
A26: 22 | B26: Add: Payments not approved
A27: 23 | B27: Add:
A28: 24 | B28: Sub-total C | D28: =SUM(D20:D25)-D26-D27 -> 0
A29: 25 | B29: Balance: Sub-total B - C
A30: 26 | B30: Pending supplier bills (Subtotal F) | D30: 0
A31: 27 | B31: Payments received during the week. | D31: 0
A32: 28 | B32: Item | D32: Amount | E32: Remarks
A33: 29 | B33: Opening balance last week (Saturday)
A34: 30 | B34: Cash withdrawn during week
A35: 31 | B35: Cash receipts / on a/c reversal
A36: 32 | B36: Subtotal D | D36: =SUM(D33:D35) -> 0
A37: 33 | B37: Cash deposited in bank during week
A38: 34 | B38: Cash expenditure during week
A39: 35 | B39: Sub total E | D39: =SUM(D37:D38) -> 0
A40: 36 | B40: Cash closing balance (Friday) (D - E) | D40: =D36-D39 -> 0
...

Sheet Summary-MV
A1: Weekly payments statement.
A2: Company:Modi Ventures | C2: Prepared by: | D2: A.Pallavi Raja
A3: Projecct: | C3: Date: | D3: 45989
A4: S No. | B4: Weekly payments (include all payments) | C4: Cr balance | D4: Amount | E4: Pay to + VRN/CRN + Desc.
A5: 1 | B5: On a/c.
A6: 2 | B6: Hire charges on a/c.
A7: 3 | B7: Hire charges Dept.
A8: 4 | B8: Job work
A9: 5 | B9: Advance
A10: 6 | B10: Other | D10: 1180 | E10: MPSVC -Accounts Management Services for the month of NOV '25
A11: 7 | B11: Other
A12: 8 | B12: Sub-total A | D12: =SUM(D5:D11) -> 1180
A13: 9 | B13: Item | C13: Last weeks payments made after statement | D13: Payment for current week - Sat to Fri | E13: Remarks
A14: 10 | B14: Cash withdrawals | D14: 0
A15: 11 | B15: Bank/book balance | D15: 8140
A16: 12 | B16: Bank/book balance - sub total A - cash withdrawals | D16: =D15-D14-D12 -> 6960
A17: 13 | B17: Add: OD limit
A18: 14 | B18: Net balance available for payments - Sub-total B | D18: =SUM(D16:D17) -> 6960
A19: 15 | B19: Payments to be made for current week.
A20: 16 | B20: Suppliers bills
A21: 17 | B21: FD - cancel/make
A22: 18 | B22: Other:
A23: 19 | B23: Other:
A24: 20 | B24: Other:
A25: 21 | B25: Other:
A26: 22 | B26: Add: Payments not approved
A27: 23 | B27: Add:
A28: 24 | B28: Sub-total C | D28: =SUM(D20:D25)-D26-D27 -> 0
A29: 25 | B29: Balance: Sub-total B - C
A30: 26 | B30: Pending supplier bills (Subtotal F) | D30: 0
A31: 27 | B31: Payments received during the week. | D31: 0
A32: 28 | B32: Item | D32: Amount | E32: Remarks
A33: 29 | B33: Opening balance last week (Saturday)
A34: 30 | B34: Cash withdrawn during week
A35: 31 | B35: Cash receipts / on a/c reversal
A36: 32 | B36: Subtotal D | D36: =SUM(D33:D35) -> 0
A37: 33 | B37: Cash deposited in bank during week
A38: 34 | B38: Cash expenditure during week
A39: 35 | B39: Sub total E | D39: =SUM(D37:D38) -> 0
A40: 36 | B40: Cash closing balance (Friday) (D - E) | D40: =D36-D39 -> 0
...

Sheet Summary-M&M
A1: Weekly payments statement.
A2: Company:Modi & Modi Constructions | C2: Prepared by: | D2: A.Pallavi Raja
A3: Projecct: | C3: Date: | D3: 45989
A4: S No. | B4: Weekly payments (include all payments) | C4: Cr balance | D4: Amount | E4: Pay to + VRN/CRN + Desc.
A5: 1 | B5: On a/c.
A6: 2 | B6: Hire charges on a/c.
A7: 3 | B7: Hire charges Dept.
A8: 4 | B8: Job work
A9: 5 | B9: Advance
A10: 6 | B10: Other | D10: 1180 | E10: MPSVC -Accounts Management Services for the month of NOV'25
A11: 7 | B11: Sub-total A | D11: =SUM(D5:D10) -> 1180
A12: 8 | B12: Item | C12: Last weeks payments made after statement | D12: Payment for current week - Sat to Fri | E12: Remarks
A13: 9 | B13: Cash withdrawals | D13: 0
A14: 10 | B14: Bank/book balance | D14: 7139
A15: 11 | B15: Bank/book balance - sub total A - cash withdrawals | D15: =D14-D13-D11 -> 5959
A16: 12 | B16: Add: OD limit
A17: 13 | B17: Net balance available for payments - Sub-total B | D17: =SUM(D15:D16) -> 5959
A18: 14 | B18: Payments to be made for current week.
A19: 15 | B19: Suppliers bills
A20: 16 | B20: FD - cancel/make
A21: 17 | B21: Other:
A22: 18 | B22: Other:
A23: 19 | B23: Other:
A24: 20 | B24: Other:
A25: 21 | B25: Add: Payments not approved
A26: 22 | B26: Add:
A27: 23 | B27: Sub-total C | D27: =SUM(D19:D24)-D25-D26 -> 0
A28: 24 | B28: Balance: Sub-total B - C
A29: 25 | B29: Pending supplier bills (Subtotal F) | D29: 0
A30: 26 | B30: Payments received during the week. | D30: 0
A31: 27 | B31: Item | D31: Amount | E31: Remarks
A32: 28 | B32: Opening balance last week (Saturday)
A33: 29 | B33: Cash withdrawn during week
A34: 30 | B34: Cash receipts / on a/c reversal
A35: 31 | B35: Subtotal D | D35: =SUM(D32:D34) -> 0
A36: 32 | B36: Cash deposited in bank during week
A37: 33 | B37: Cash expenditure during week
A38: 34 | B38: Sub total E | D38: =SUM(D36:D37) -> 0
A39: 35 | B39: Cash closing balance (Friday) (D - E) | D39: =D35-D38 -> 0
A40: 36 | B40: Supplier bills statement
...

Sheet Summary-PMB
A1: Weekly payments statement.
A2: Company:Paramount Builders | C2: Prepared by: | D2: A.Pallavi Raja
A3: Projecct: | C3: Date: | D3: 45933
A4: S No. | B4: Weekly payments (include all payments) | C4: Cr balance | D4: Amount | E4: Pay to + VRN/CRN + Desc.
A5: 1 | B5: On a/c.
A6: 2 | B6: Hire charges on a/c.
A7: 3 | B7: Hire charges Dept.
A8: 4 | B8: Job work
A9: 5 | B9: Advance
A10: 6 | B10: Other | D10: =1180 -> 1180 | E10: MPSVC -CA & CS Services for the month of NOV'25
A11: 7 | B11: Other
A12: 8 | B12: Sub-total A | D12: =SUM(D5:D11) -> 1180
A13: 9 | B13: Item | C13: Last weeks payments made after statement | D13: Payment for current week - Sat to Fri | E13: Remarks
A14: 10 | B14: Cash withdrawals | D14: 0
A15: 11 | B15: Bank/book balance | D15: 5496
A16: 12 | B16: Bank/book balance - sub total A - cash withdrawals | D16: =D15-D14-D12 -> 4316
A17: 13 | B17: Add: OD limit
A18: 14 | B18: Net balance available for payments - Sub-total B | D18: =SUM(D16:D17) -> 4316
A19: 15 | B19: Payments to be made for current week.
A20: 16 | B20: Suppliers bills
A21: 17 | B21: FD - cancel/make
A22: 18 | B22: Other:
A23: 19 | B23: Other:
A24: 20 | B24: Other:
A25: 21 | B25: Other:
A26: 22 | B26: Add: Payments not approved
A27: 23 | B27: Add:
A28: 24 | B28: Sub-total C | D28: =SUM(D20:D25)-D26-D27 -> 0
A29: 25 | B29: Balance: Sub-total B - C
A30: 26 | B30: Pending supplier bills (Subtotal F) | D30: 0
A31: 27 | B31: Payments received during the week. | D31: 0
A32: 28 | B32: Item | D32: Amount | E32: Remarks
A33: 29 | B33: Opening balance last week (Saturday)
A34: 30 | B34: Cash withdrawn during week
A35: 31 | B35: Cash receipts / on a/c reversal
A36: 32 | B36: Subtotal D | D36: =SUM(D33:D35) -> 0
A37: 33 | B37: Cash deposited in bank during week
A38: 34 | B38: Cash expenditure during week
A39: 35 | B39: Sub total E | D39: =SUM(D37:D38) -> 0
A40: 36 | B40: Cash closing balance (Friday) (D - E) | D40: =D36-D39 -> 0
...

Sheet Summary-K&M
A1: Weekly payments statement.
A2: Company:Kadakia & Modi Housing | C2: Prepared by: | D2: A.Pallavi Raja
A3: Projecct: | C3: Date: | D3: 45989
A4: S No. | B4: Weekly payments (include all payments) | C4: Cr balance | D4: Amount | E4: Pay to + VRN/CRN + Desc.
A5: 1 | B5: On a/c.
A6: 2 | B6: Hire charges on a/c.
A7: 3 | B7: Hire charges Dept.
A8: 4 | B8: Job work
A9: 5 | B9: Advance
A10: 6 | B10: Other | D10: =530+1180 -> 1710 | E10: MPSVC -Accounts Management Services for the month of NOV'25
A11: 7 | B11: Other | D11: 35374 | E11: Janardhan Prasad towards granite tile-fiitter
A12: 8 | B12: Sub-total A | D12: =SUM(D5:D11) -> 37084
A13: 9 | B13: Item | C13: Last weeks payments made after statement | D13: Payment for current week - Sat to Fri | E13: Remarks
A14: 10 | B14: Cash withdrawals | D14: 0
A15: 11 | B15: Bank/book balance | D15: 3460
A16: 12 | B16: Bank/book balance - sub total A - cash withdrawals | D16: =D15-D14-D12 -> -33624
A17: 13 | B17: Add: OD limit
A18: 14 | B18: Net balance available for payments - Sub-total B | D18: =SUM(D16:D17) -> -33624
A19: 15 | B19: Payments to be made for current week.
A20: 16 | B20: Suppliers bills
A21: 17 | B21: FD - cancel/make
A22: 18 | B22: Other:
A23: 19 | B23: Other:
A24: 20 | B24: Other:
A25: 21 | B25: Other:
A26: 22 | B26: Add: Payments not approved
A27: 23 | B27: Add:
A28: 24 | B28: Sub-total C | D28: =SUM(D20:D25)-D26-D27 -> 0
A29: 25 | B29: Balance: Sub-total B - C
A30: 26 | B30: Pending supplier bills (Subtotal F) | D30: 0
A31: 27 | B31: Payments received during the week. | D31: 0
A32: 28 | B32: Item | D32: Amount | E32: Remarks
A33: 29 | B33: Opening balance last week (Saturday)
A34: 30 | B34: Cash withdrawn during week
A35: 31 | B35: Cash receipts / on a/c reversal
A36: 32 | B36: Subtotal D | D36: =SUM(D33:D35) -> 0
A37: 33 | B37: Cash deposited in bank during week
A38: 34 | B38: Cash expenditure during week
A39: 35 | B39: Sub total E | D39: =SUM(D37:D38) -> 0
A40: 36 | B40: Cash closing balance (Friday) (D - E) | D40: =D36-D39 -> 0
...

Sheet  Summary- Timmapur
A1: Weekly payments statement.
A2: Company: Modi Realty Timmapur LLP | C2: Prepared by: | D2: A.Pallavi Raja
A3: Project:Blue Bell Residency at Timmapur | C3: Date: | D3: 45933
A4: S No. | B4: Weekly payments (include all payments) | C4: Cr balance | D4: Amount | E4: Pay to + VRN/CRN + Desc.
A5: 1 | B5: On a/c.
A6: 2 | B6: Hire charges on a/c.
A7: 3 | B7: Hire charges Dept.
A8: 4 | B8: Job work
A9: 5 | B9: Advance
A10: 6 | B10: Other | D10: 129 | E10: MHSVC Services towards PO'S bill no 10208
A11: 7 | B11: Other | D11: =18775+13836 -> 32611 | E11: I.T,E&D,promotion exp etc for month of NOV'25
A12: 8 | B12: Other | D12: 4455 | E12: Shruthi Agarwal Professional fees for form-8
A13: 9 | B13: Other | D13: 40000 | E13: Sai Krishna Salary for the month of NOV'25 Approx
A14: 10 | B14: Other | D14: 587 | E14: TDS for the Month of Nov'25
A15: 11 | B15: Other | D15: =18775+5900+1770 -> 26445 | E15: MPSVC-Accounts management Services,& IT Services CA & CS Services for the month of OCT'25&NOV'25
A16: 12 | B16: Sub-total A | D16: =SUM(D5:D15) -> 104227
A17: 13 | B17: Item | C17: Last weeks payments made after statement | D17: Payment for current week - Sat to Fri | E17: Remarks
A18: 14 | B18: Cash withdrawals | D18: 0
A19: 15 | B19: Bank/book balance | D19: 2635
A20: 16 | B20: Bank/book balance - sub total A - cash withdrawals | D20: =D19-D18-D16 -> -101592
A21: 17 | B21: Add: OD limit | D21: 0
A22: 18 | B22: Net balance available for payments - Sub-total B | D22: =SUM(D20:D21) -> -101592
A23: 19 | B23: Payments to be made for current week.
A24: 20 | B24: Suppliers bills
A25: 21 | B25: FD - cancel/make
A26: 22 | B26: Other:
A27: 23 | B27: Other:
A28: 24 | B28: Other:
A29: 25 | B29: Other:
A30: 26 | B30: Add: Payments not approved
A31: 27 | B31: Add:
A32: 28 | B32: Sub-total C | D32: =SUM(D24:D29)-D30-D31 -> 0
A33: 29 | B33: Balance: Sub-total B - C
A34: 30 | B34: Pending supplier bills (Subtotal F) | D34: 0
A35: 31 | B35: Payments received during the week. | D35: 0
A36: 32 | B36: Item | D36: Amount | E36: Remarks
A37: 33 | B37: Opening balance last week (Saturday)
A38: 34 | B38: Cash withdrawn during week
A39: 35 | B39: Cash receipts / on a/c reversal
A40: 36 | B40: Subtotal D | D40: =SUM(D37:D39) -> 0
...

Sheet Summary-Vikarabad
A1: Weekly payments statement.
A2: Company: Modi Realty Vikarabad LLP | C2: Prepared by: | D2: A.Pallavi Raja
A3: Project:Blue bell Residency | C3: Date: | D3: 45989
A4: S No. | B4: Weekly payments (include all payments) | C4: Cr balance | D4: Amount | E4: Pay to + VRN/CRN + Desc.
A5: 1 | B5: On a/c.
A6: 2 | B6: Hire charges on a/c.
A7: 3 | B7: Hire charges Dept.
A8: 4 | B8: Job work
A9: 5 | B9: Advance
A10: 6 | B10: Other | D10: 4455 | E10: Shruthi Agarwal Professional fees for form-8
A11: 7 | B11: Other | D11: 9440 | E11: MPSVC-Accounts Management Services,CA & CS Services for the month of NOV'25
A12: 8 | B12: Sub-total A | D12: =SUM(D5:D11) -> 13895
A13: 9 | B13: Item | C13: Last weeks payments made after statement | D13: Payment for current week - Sat to Fri | E13: Remarks
A14: 10 | B14: Cash withdrawals | D14: 0
A15: 11 | B15: Bank/book balance | D15: -897154
A16: 12 | B16: Bank/book balance - sub total A - cash withdrawals | D16: =D15-D14-D12 -> -911049
A17: 13 | B17: Add: OD limit | D17: 900000
A18: 14 | B18: Net balance available for payments - Sub-total B | D18: =SUM(D16:D17) -> -11049
A19: 15 | B19: Payments to be made for current week.
A20: 16 | B20: Suppliers bills
A21: 17 | B21: FD - cancel/make
A22: 18 | B22: Other:
A23: 19 | B23: Other:
A24: 20 | B24: Other:
A25: 21 | B25: Other:
A26: 22 | B26: Add: Payments not approved
A27: 23 | B27: Add:
A28: 24 | B28: Sub-total C | D28: =SUM(D20:D25)-D26-D27 -> 0
A29: 25 | B29: Balance: Sub-total B - C
A30: 26 | B30: Pending supplier bills (Subtotal F) | D30: 0
A31: 27 | B31: Payments received during the week. | D31: 0
A32: 28 | B32: Item | D32: Amount | E32: Remarks
A33: 29 | B33: Opening balance last week (Saturday)
A34: 30 | B34: Cash withdrawn during week
A35: 31 | B35: Cash receipts / on a/c reversal
A36: 32 | B36: Subtotal D | D36: =SUM(D33:D35) -> 0
A37: 33 | B37: Cash deposited in bank during week
A38: 34 | B38: Cash expenditure during week
A39: 35 | B39: Sub total E | D39: =SUM(D37:D38) -> 0
A40: 36 | B40: Cash closing balance (Friday) (D - E) | D40: =D36-D39 -> 0
...

Sheet  summary- Vikaraba(2)
A1: Weekly payments statement.
A2: Company: Modi Realty Vikarabad LLP | C2: Prepared by: | D2: Pallavi
A3: Project:Blue bell Residency | C3: Date: | D3: 45898
A4: S No. | B4: Weekly payments (include all payments) | C4: Cr balance | D4: Amount | E4: Pay to + VRN/CRN + Desc.
A5: 1 | B5: On a/c.
A6: 2 | B6: Hire charges on a/c.
A7: 3 | B7: Hire charges Dept.
A8: 4 | B8: Job work
A9: 5 | B9: Advance
A10: 6 | B10: Other
A11: 7 | B11: Other | D11: =5900+1770 -> 7670 | E11: MPSVC-Accounts Management Services,CA & CS Services for the month of Aug'25
A12: 8 | B12: Sub-total A | D12: =SUM(D5:D11) -> 7670
A13: 9 | B13: Item | C13: Last weeks payments made after statement | D13: Payment for current week - Sat to Fri | E13: Remarks
A14: 10 | B14: Cash withdrawals | D14: 0
A15: 11 | B15: Bank/book balance | D15: -875341
A16: 12 | B16: Bank/book balance - sub total A - cash withdrawals | D16: =D15-D14-D12 -> -883011
A17: 13 | B17: Add: OD limit | D17: 900000
A18: 14 | B18: Net balance available for payments - Sub-total B | D18: =SUM(D16:D17) -> 16989
A19: 15 | B19: Payments to be made for current week.
A20: 16 | B20: Suppliers bills
A21: 17 | B21: FD - cancel/make
A22: 18 | B22: Other:
A23: 19 | B23: Other:
A24: 20 | B24: Other:
A25: 21 | B25: Other:
A26: 22 | B26: Add: Payments not approved
A27: 23 | B27: Add:
A28: 24 | B28: Sub-total C | D28: =SUM(D20:D25)-D26-D27 -> 0
A29: 25 | B29: Balance: Sub-total B - C
A30: 26 | B30: Pending supplier bills (Subtotal F) | D30: 0
A31: 27 | B31: Payments received during the week. | D31: 0
A32: 28 | B32: Item | D32: Amount | E32: Remarks
A33: 29 | B33: Opening balance last week (Saturday)
A34: 30 | B34: Cash withdrawn during week
A35: 31 | B35: Cash receipts / on a/c reversal
A36: 32 | B36: Subtotal D | D36: =SUM(D33:D35) -> 0
A37: 33 | B37: Cash deposited in bank during week
A38: 34 | B38: Cash expenditure during week
A39: 35 | B39: Sub total E | D39: =SUM(D37:D38) -> 0
A40: 36 | B40: Cash closing balance (Friday) (D - E) | D40: =D36-D39 -> 0
...

Sheet Summary-SC&R LLP
A1: Weekly payments statement.
A2: Company: | B2: Serene Clubs & Resorts LLP | C2: Prepared by: | D2: A.Pallavi Raja
A3: Projecct: | C3: Date: | D3: 45989
A4: S No. | B4: Weekly payments (include all payments) | C4: Cr balance | D4: Amount | E4: Pay to + VRN/CRN + Desc.
A5: 1 | B5: On a/c.
A6: 2 | B6: Hire charges on a/c.
A7: 3 | B7: Hire charges Dept.
A8: 4 | B8: Job work
A9: 5 | B9: Advance
A10: 6 | B10: Other | D10: =1770+5900 -> 7670 | E10: MPSVC -Accounts Managemnt Services,CA & CS Services for the month of NOV'25
A11: 7 | B11: Other | D11: 4455 | E11: Shruthi Agarwal Professional fees for form-8
A12: 8 | B12: Sub-total A | D12: =SUM(D5:D11) -> 12125
A13: 9 | B13: Item | C13: Last weeks payments made after statement | D13: Payment for current week - Sat to Fri | E13: Remarks
A14: 10 | B14: Cash withdrawals | D14: 0
A15: 11 | B15: Bank/book balance | D15: 1957
A16: 12 | B16: Bank/book balance - sub total A - cash withdrawals | D16: =D15-D14-D12 -> -10168
A17: 13 | B17: Add: OD limit
A18: 14 | B18: Net balance available for payments - Sub-total B | D18: =SUM(D16:D17) -> -10168
A19: 15 | B19: Payments to be made for current week.
A20: 16 | B20: Suppliers bills
A21: 17 | B21: FD - cancel/make
A22: 18 | B22: Other:
A23: 19 | B23: Other:
A24: 20 | B24: Other:
A25: 21 | B25: Other:
A26: 22 | B26: Add: Payments not approved
A27: 23 | B27: Add:
A28: 24 | B28: Sub-total C | D28: =SUM(D20:D25)-D26-D27 -> 0
A29: 25 | B29: Balance: Sub-total B - C
A30: 26 | B30: Pending supplier bills (Subtotal F) | D30: 0
A31: 27 | B31: Payments received during the week. | D31: 0
A32: 28 | B32: Item | D32: Amount | E32: Remarks
A33: 29 | B33: Opening balance last week (Saturday)
A34: 30 | B34: Cash withdrawn during week
A35: 31 | B35: Cash receipts / on a/c reversal
A36: 32 | B36: Subtotal D | D36: =SUM(D33:D35) -> 0
A37: 33 | B37: Cash deposited in bank during week
A38: 34 | B38: Cash expenditure during week
A39: 35 | B39: Sub total E | D39: =SUM(D37:D38) -> 0
A40: 36 | B40: Cash closing balance (Friday) (D - E) | D40: =D36-D39 -> 0
...

Sheet Summary-MFHHLLP
A1: Weekly payments statement.
A2: Company: | B2: Modi Farm House Hyderabad LLP | C2: Prepared by: | D2: A.Pallavi Raja
A3: Projecct: | C3: Date: | D3: 45989
A4: S No. | B4: Weekly payments (include all payments) | C4: Cr balance | D4: Amount | E4: Pay to + VRN/CRN + Desc.
A5: 1 | B5: On a/c.
A6: 2 | B6: Hire charges on a/c.
A7: 3 | B7: Hire charges Dept.
A8: 4 | B8: Job work
A9: 5 | B9: Advance | D9: 48000 | E9: Housing loan Incentives for Prabhakat Reddy,Rambabu,Pavan ,Mahender
A10: 6 | B10: Other | D10: =898+1770+1180 -> 3848 | E10: MPSVC -Accounts Managemnt Services,CA & CS Services for the month of NOV'25
A11: 7 | B11: Other | D11: 4455 | E11: Shruthi Agarwal Professional fees
A12: 8 | B12: Other | D12: 15000 | E12: towards Final Settlement of Syed Golam Sarwar 2nd Installment
A13: 9 | B13: Sub-total A | D13: =SUM(D5:D11) -> 56303
A14: 10 | B14: Item | C14: Last weeks payments made after statement | D14: Payment for current week - Sat to Fri | E14: Remarks
A15: 11 | B15: Cash withdrawals | D15: 0
A16: 12 | B16: Bank/book balance | D16: 5523
A17: 13 | B17: Bank/book balance - sub total A - cash withdrawals | D17: =D16-D15-D13 -> -50780
A18: 14 | B18: Add: OD limit
A19: 15 | B19: Net balance available for payments - Sub-total B | D19: =SUM(D17:D18) -> -50780
A20: 16 | B20: Payments to be made for current week.
A21: 17 | B21: Suppliers bills
A22: 18 | B22: FD - cancel/make
A23: 19 | B23: Other:
A24: 20 | B24: Other:
A25: 21 | B25: Other:
A26: 22 | B26: Other:
A27: 23 | B27: Add: Payments not approved
A28: 24 | B28: Add:
A29: 25 | B29: Sub-total C | D29: =SUM(D21:D26)-D27-D28 -> 0
A30: 26 | B30: Balance: Sub-total B - C
A31: 27 | B31: Pending supplier bills (Subtotal F) | D31: 0
A32: 28 | B32: Payments received during the week. | D32: 0
A33: 29 | B33: Item | D33: Amount | E33: Remarks
A34: 30 | B34: Opening balance last week (Saturday)
A35: 31 | B35: Cash withdrawn during week
A36: 32 | B36: Cash receipts / on a/c reversal
A37: 33 | B37: Subtotal D | D37: =SUM(D34:D36) -> 0
A38: 34 | B38: Cash deposited in bank during week
A39: 35 | B39: Cash expenditure during week
A40: 36 | B40: Sub total E | D40: =SUM(D38:D39) -> 0
...

Sheet Summary-Serene LLP
A1: Weekly payments statement.
A2: Company: | B2: Serene Constructions LLP | C2: Prepared by: | D2: A.Pallavi Raja
A3: Projecct: | C3: Date: | D3: ='1. Bank balance statement'!B3 -> 45996
A4: S No. | B4: Weekly payments (include all payments) | C4: Cr balance | D4: Amount | E4: Pay to + VRN/CRN + Desc.
A5: 1 | B5: On a/c.
A6: 2 | B6: Hire charges on a/c.
A7: 3 | B7: Hire charges Dept.
A8: 4 | B8: Job work
A9: 5 | B9: Advance | D9: 713 | E9: MHSVC Services towards PO,S & WO'S service charges
A10: 6 | B10: Other | D10: 4952 | E10: MPSVC -Accounts Managemnt Services,CA & CS Services for the month of NOV '25
A11: 7 | B11: Other | D11: 125447 | E11: IQ Constructions towards aganist STP work & Shuttering and bar bending work done bill no 015,016
A12: 8 | B12: Other | D12: 183900 | E12: R6 towards M-25 Pump bills no 301,299,300
A13: 9 | B13: Other | D13: 85716 | E13: T kurmanna towards STP Soil shifting from other site etc
A14: 10 | B14: Other | D14: 20000 | E14: Jayaram Nenavath towards STP collection tank water proofing work done
A15: 11 | B15: Other | D15: 4455 | E15: Shruthi Agarwal Professional Services fees
A16: 12 | B16: Other | D16: 10601 | E16: Kailash Pandey towards STP Collection tank external plastering work done
A17: 13 | B17: Sub-total A | D17: =SUM(D5:D16) -> 435784
A18: 14 | B18: Item | C18: Last weeks payments made after statement | D18: Payment for current week - Sat to Fri | E18: Remarks
A19: 15 | B19: Cash withdrawals | D19: 0
A20: 16 | B20: Bank/book balance | D20: 42243
A21: 17 | B21: Bank/book balance - sub total A - cash withdrawals | D21: =D20-D19-D17 -> -393541
A22: 18 | B22: Add: OD limit
A23: 19 | B23: Net balance available for payments - Sub-total B | D23: =SUM(D21:D22) -> -393541
A24: 20 | B24: Payments to be made for current week.
A25: 21 | B25: Suppliers bills
A26: 22 | B26: FD - cancel/make
A27: 23 | B27: Other:
A28: 24 | B28: Other:
A29: 25 | B29: Other:
A30: 26 | B30: Other:
A31: 27 | B31: Add: Payments not approved
A32: 28 | B32: Add:
A33: 29 | B33: Sub-total C | D33: =SUM(D25:D30)-D31-D32 -> 0
A34: 30 | B34: Balance: Sub-total B - C
A35: 31 | B35: Pending supplier bills (Subtotal F) | D35: 0
A36: 32 | B36: Payments received during the week. | D36: 0
A37: 33 | B37: Item | D37: Amount | E37: Remarks
A38: 34 | B38: Opening balance last week (Saturday)
A39: 35 | B39: Cash withdrawn during week
A40: 36 | B40: Cash receipts / on a/c reversal
...

Sheet  summary- MCS
A1: Weekly payments statement.
A2: Company:Modi Consultancy Services | C2: Prepared by: | D2: Pallavi
A3: Project:NA | C3: Date: | D3: 45898
A4: S No. | B4: Weekly payments (include all payments) | C4: Cr balance | D4: Amount | E4: Pay to + VRN/CRN + Desc.
A5: 1 | B5: On a/c.
A6: 2 | B6: Hire charges on a/c.
A7: 3 | B7: Hire charges Dept.
A8: 4 | B8: Job work
A9: 5 | B9: Advance
A10: 6 | B10: Other | D10: 41250 | E10: towards Villa 3,4 Maintances Charges for F.Y24-25
A11: 7 | B11: Other | D11: 66755 | E11: Hoarding rent Aug-25
A12: 8 | B12: Other | D12: 1180 | E12: MPSVC-Accounts Management Services for the month of Aug'25
A13: 9 | B13: Sub-total A | D13: =SUM(D5:D12) -> 109185
A14: 10 | B14: Item | C14: Last weeks payments made after statement | D14: Payment for current week - Sat to Fri | E14: Remarks
A15: 11 | B15: Cash withdrawals | D15: 0
A16: 12 | B16: Bank/book balance | D16: =112978-7822 -> 105156
A17: 13 | B17: Bank/book balance - sub total A - cash withdrawals | D17: =D16-D15-D13 -> -4029
A18: 14 | B18: Add: OD limit | D18: 180000
A19: 15 | B19: Net balance available for payments - Sub-total B | D19: =SUM(D17:D18) -> 175971
A20: 16 | B20: Payments to be made for current week.
A21: 17 | B21: Suppliers bills
A22: 18 | B22: FD - cancel/make
A23: 19 | B23: Other:
A24: 20 | B24: Other:
A25: 21 | B25: Other:
A26: 22 | B26: Other:
A27: 23 | B27: Add: Payments not approved
A28: 24 | B28: Add:
A29: 25 | B29: Sub-total C | D29: =SUM(D21:D26)-D27-D28 -> 0
A30: 26 | B30: Balance: Sub-total B - C
A31: 27 | B31: Pending supplier bills (Subtotal F) | D31: 0
A32: 28 | B32: Payments received during the week. | D32: =104160+25960+11760+11760 -> 153640
A33: 29 | B33: Item | D33: Amount | E33: Remarks
A34: 30 | B34: Opening balance last week (Saturday)
A35: 31 | B35: Cash withdrawn during week
A36: 32 | B36: Cash receipts / on a/c reversal
A37: 33 | B37: Subtotal D | D37: =SUM(D34:D36) -> 0
A38: 34 | B38: Cash deposited in bank during week
A39: 35 | B39: Cash expenditure during week
A40: 36 | B40: Sub total E | D40: =SUM(D38:D39) -> 0
...

Sheet Summary-SSLLP
A1: Weekly payments statement.
A2: Company:Summit Sales LLP - ICICI BANK | C2: Prepared by: | D2: A.Pallavi Raja
A3: Project: | C3: Date: | D3: ='1. Bank balance statement'!B3 -> 45996
A4: S No. | B4: Weekly payments (include all payments) | C4: Cr balance | D4: Amount | E4: Pay to + VRN/CRN + Desc.
A5: 1 | B5: On a/c.
A6: 2 | B6: Hire charges on a/c.
A7: 3 | B7: Hire charges Dept.
A8: 4 | B8: Job work
A9: 5 | B9: Advance | D9: 10000 | E9: Hemendra final settlement 1st Installment
A10: 6 | B10: Other | D10: 4455 | E10: Shruthi Agarwal Professional Services fees
A11: 7 | B11: Other | D11: 30000 | E11: towards Final Settlement of D Jaya Pradha 2nd Installment
A12: 8 | B12: Other | D12: =2950+1770+1180 -> 5900 | E12: MPSVC-Accounts management Services,CA & CS Services for the month of NOV'25
A13: 9 | B13: Sub-total A | D13: =SUM(D5:D12) -> 50355
A14: 10 | B14: Item | C14: Last weeks payments made after statement | D14: Payment for current week - Sat to Fri | E14: Remarks
A15: 11 | B15: Cash withdrawals | D15: 0
A16: 12 | B16: Bank/book balance | D16: 22490
A17: 13 | B17: Bank/book balance - sub total A - cash withdrawals | D17: =D16-D15-D13 -> -27865
A18: 14 | B18: Add: OD limit | D18: 0
A19: 15 | B19: Net balance available for payments - Sub-total B | D19: =SUM(D17:D18) -> -27865
A20: 16 | B20: Payments to be made for current week.
A21: 17 | B21: Suppliers bills
A22: 18 | B22: FD - cancel/make
A23: 19 | B23: Other:
A24: 20 | B24: Other:
A25: 21 | B25: Other:
A26: 22 | B26: Other:
A27: 23 | B27: Add: Payments not approved
A28: 24 | B28: Add:
A29: 25 | B29: Sub-total C | D29: =SUM(D21:D26)-D27-D28 -> 0
A30: 26 | B30: Balance: Sub-total B - C
A31: 27 | B31: Pending supplier bills (Subtotal F) | D31: 0
A32: 28 | B32: Payments received during the week. | D32: 0
A33: 29 | B33: Item | D33: Amount | E33: Remarks
A34: 30 | B34: Opening balance last week (Saturday)
A35: 31 | B35: Cash withdrawn during week
A36: 32 | B36: Cash receipts / on a/c reversal
A37: 33 | B37: Subtotal D | D37: =SUM(D34:D36) -> 0
A38: 34 | B38: Cash deposited in bank during week
A39: 35 | B39: Cash expenditure during week
A40: 36 | B40: Sub total E | D40: =SUM(D38:D39) -> 0
...

Sheet Summary-NQB
A1: Weekly payments statement.
A2: Company: M &M Association | B2: N Square Biotech Pvt Ltd | C2: Prepared by: | D2: A.Pallavi Raja
A3: Projecct: | C3: Date: | D3: ='1. Bank balance statement'!B3 -> 45996
A4: S No. | B4: Weekly payments (include all payments) | C4: Cr balance | D4: Amount | E4: Pay to + VRN/CRN + Desc.
A5: 1 | B5: On a/c.
A6: 2 | B6: Hire charges on a/c.
A7: 3 | B7: Hire charges Dept.
A8: 4 | B8: Job work
A9: 5 | B9: Advance
A10: 6 | B10: Other | D10: 6805 | E10: TDS for the Month of NOV'25
A11: 7 | B11: Other | D11: 40230 | E11: AS Agarwal. towards fee for professional services F.Y 25
A12: 8 | B12: Other | D12: 33264 | E12: Shruthi Agarwal Professional services-annual returns
A13: 9 | B13: Other | D13: =2360+1180 -> 3540 | E13: MPSVC Services towards CA & CS & Accounts management services
A14: 10 | B14: Other
A15: 11 | B15: Sub-total A | D15: =SUM(D5:D14) -> 83839
A16: 12 | B16: Item | C16: Last weeks payments made after statement | D16: Payment for current week - Sat to Fri | E16: Remarks
A17: 13 | B17: Cash withdrawals | D17: 0
A18: 14 | B18: Bank/book balance | D18: 741
A19: 15 | B19: Bank/book balance - sub total A - cash withdrawals | D19: =D18-D17-D15 -> -83098
A20: 16 | B20: Add: OD limit
A21: 17 | B21: Net balance available for payments - Sub-total B | D21: =SUM(D19:D20) -> -83098
A22: 18 | B22: Payments to be made for current week.
A23: 19 | B23: Suppliers bills
A24: 20 | B24: FD - cancel/make
A25: 21 | B25: Other:
A26: 22 | B26: Other:
A27: 23 | B27: Other:
A28: 24 | B28: Other:
A29: 25 | B29: Add: Payments not approved
A30: 26 | B30: Add:
A31: 27 | B31: Sub-total C | D31: =SUM(D23:D28)-D29-D30 -> 0
A32: 28 | B32: Balance: Sub-total B - C
A33: 29 | B33: Pending supplier bills (Subtotal F) | D33: 0
A34: 30 | B34: Payments received during the week. | D34: 1500000 | E34: MPPL
A35: 31 | B35: Item | D35: Amount | E35: Remarks
A36: 32 | B36: Opening balance last week (Saturday)
A37: 33 | B37: Cash withdrawn during week
A38: 34 | B38: Cash receipts / on a/c reversal
A39: 35 | B39: Subtotal D | D39: =SUM(D36:D38) -> 0
A40: 36 | B40: Cash deposited in bank during week
...

Sheet Summary-MRGVHydLLP
A1: Weekly payments statement.
A2: Company:Modi Realty GV Hyderabad LLP | C2: Prepared by: | D2: A.Pallavi Raja
A3: Project: | C3: Date: | D3: ='1. Bank balance statement'!B3 -> 45996
A4: S No. | B4: Weekly payments (include all payments) | C4: Cr balance | D4: Amount | E4: Pay to + VRN/CRN + Desc.
A5: 1 | B5: On a/c.
A6: 2 | B6: Hire charges on a/c.
A7: 3 | B7: Hire charges Dept.
A8: 4 | B8: Job work
A9: 5 | B9: Advance
A10: 6 | B10: Other
A11: 7 | B11: Other | D11: 4455 | E11: Shruthi Agarwal Professional Services fees
A12: 8 | B12: Other | D12: =1770 -> 1770 | E12: MPSVC-Accounts management Services,CA & CS Services for the month of NOV'25
A13: 9 | B13: Sub-total A | D13: =SUM(D5:D12) -> 6225
A14: 10 | B14: Item | C14: Last weeks payments made after statement | D14: Payment for current week - Sat to Fri | E14: Remarks
A15: 11 | B15: Cash withdrawals | D15: 0
A16: 12 | B16: Bank/book balance | D16: 934
A17: 13 | B17: Bank/book balance - sub total A - cash withdrawals | D17: =D16-D15-D13 -> -5291
A18: 14 | B18: Add: OD limit | D18: 0
A19: 15 | B19: Net balance available for payments - Sub-total B | D19: =SUM(D17:D18) -> -5291
A20: 16 | B20: Payments to be made for current week.
A21: 17 | B21: Suppliers bills
A22: 18 | B22: FD - cancel/make
A23: 19 | B23: Other:
A24: 20 | B24: Other:
A25: 21 | B25: Other:
A26: 22 | B26: Other:
A27: 23 | B27: Add: Payments not approved
A28: 24 | B28: Add:
A29: 25 | B29: Sub-total C | D29: =SUM(D21:D26)-D27-D28 -> 0
A30: 26 | B30: Balance: Sub-total B - C
A31: 27 | B31: Pending supplier bills (Subtotal F) | D31: 0
A32: 28 | B32: Payments received during the week. | D32: 0
A33: 29 | B33: Item | D33: Amount | E33: Remarks
A34: 30 | B34: Opening balance last week (Saturday)
A35: 31 | B35: Cash withdrawn during week
A36: 32 | B36: Cash receipts / on a/c reversal
A37: 33 | B37: Subtotal D | D37: =SUM(D34:D36) -> 0
A38: 34 | B38: Cash deposited in bank during week
A39: 35 | B39: Cash expenditure during week
A40: 36 | B40: Sub total E | D40: =SUM(D38:D39) -> 0
...

Sheet Summary -Manilal
A1: Weekly payments statement.
A2: Company:Manilal Modi Charitable Foundation | C2: Prepared by: | D2: A.Pallavi Raja
A3: Project: | C3: Date: | D3: ='1. Bank balance statement'!B3 -> 45996
A4: S No. | B4: Weekly payments (include all payments) | C4: Cr balance | D4: Amount | E4: Pay to + VRN/CRN + Desc.
A5: 1 | B5: On a/c.
A6: 2 | B6: Hire charges on a/c.
A7: 3 | B7: Hire charges Dept.
A8: 4 | B8: Job work
A9: 5 | B9: Advance
A10: 6 | B10: Other
A11: 7 | B11: Other
A12: 8 | B12: Other | D12: =1180+1180 -> 2360 | E12: MPSVC-Accounts management Services,CA & CS Services for the month of NOV'25
A13: 9 | B13: Sub-total A | D13: =SUM(D5:D12) -> 2360
A14: 10 | B14: Item | C14: Last weeks payments made after statement | D14: Payment for current week - Sat to Fri | E14: Remarks
A15: 11 | B15: Cash withdrawals | D15: 0
A16: 12 | B16: Bank/book balance | D16: 6083
A17: 13 | B17: Bank/book balance - sub total A - cash withdrawals | D17: =D16-D15-D13 -> 3723
A18: 14 | B18: Add: OD limit | D18: 0
A19: 15 | B19: Net balance available for payments - Sub-total B | D19: =SUM(D17:D18) -> 3723
A20: 16 | B20: Payments to be made for current week.
A21: 17 | B21: Suppliers bills
A22: 18 | B22: FD - cancel/make
A23: 19 | B23: Other:
A24: 20 | B24: Other:
A25: 21 | B25: Other:
A26: 22 | B26: Other:
A27: 23 | B27: Add: Payments not approved
A28: 24 | B28: Add:
A29: 25 | B29: Sub-total C | D29: =SUM(D21:D26)-D27-D28 -> 0
A30: 26 | B30: Balance: Sub-total B - C
A31: 27 | B31: Pending supplier bills (Subtotal F) | D31: 0
A32: 28 | B32: Payments received during the week. | D32: 0
A33: 29 | B33: Item | D33: Amount | E33: Remarks
A34: 30 | B34: Opening balance last week (Saturday)
A35: 31 | B35: Cash withdrawn during week
A36: 32 | B36: Cash receipts / on a/c reversal
A37: 33 | B37: Subtotal D | D37: =SUM(D34:D36) -> 0
A38: 34 | B38: Cash deposited in bank during week
A39: 35 | B39: Cash expenditure during week
A40: 36 | B40: Sub total E | D40: =SUM(D38:D39) -> 0
...

Sheet Summary-Vista Homes
A1: Weekly payments statement.
A2: Company:Vista Homes | C2: Prepared by: | D2: A.Pallavi Raja
A3: Project: | C3: Date: | D3: ='1. Bank balance statement'!B3 -> 45996
A4: S No. | B4: Weekly payments (include all payments) | C4: Cr balance | D4: Amount | E4: Pay to + VRN/CRN + Desc.
A5: 1 | B5: On a/c.
A6: 2 | B6: Hire charges on a/c.
A7: 3 | B7: Hire charges Dept.
A8: 4 | B8: Job work
A9: 5 | B9: Advance
A10: 6 | B10: Other
A11: 7 | B11: Other
A12: 8 | B12: Other | D12: =1180 -> 1180 | E12: MPSVC-Accounts management Services,CA & CS Services for the month of NOV '25
A13: 9 | B13: Sub-total A | D13: =SUM(D5:D12) -> 1180
A14: 10 | B14: Item | C14: Last weeks payments made after statement | D14: Payment for current week - Sat to Fri | E14: Remarks
A15: 11 | B15: Cash withdrawals | D15: 0
A16: 12 | B16: Bank/book balance | D16: 18973
A17: 13 | B17: Bank/book balance - sub total A - cash withdrawals | D17: =D16-D15-D13 -> 17793
A18: 14 | B18: Add: OD limit | D18: 0
A19: 15 | B19: Net balance available for payments - Sub-total B | D19: =SUM(D17:D18) -> 17793
A20: 16 | B20: Payments to be made for current week.
A21: 17 | B21: Suppliers bills
A22: 18 | B22: FD - cancel/make
A23: 19 | B23: Other:
A24: 20 | B24: Other:
A25: 21 | B25: Other:
A26: 22 | B26: Other:
A27: 23 | B27: Add: Payments not approved
A28: 24 | B28: Add:
A29: 25 | B29: Sub-total C | D29: =SUM(D21:D26)-D27-D28 -> 0
A30: 26 | B30: Balance: Sub-total B - C
A31: 27 | B31: Pending supplier bills (Subtotal F) | D31: 0
A32: 28 | B32: Payments received during the week. | D32: 0
A33: 29 | B33: Item | D33: Amount | E33: Remarks
A34: 30 | B34: Opening balance last week (Saturday)
A35: 31 | B35: Cash withdrawn during week
A36: 32 | B36: Cash receipts / on a/c reversal
A37: 33 | B37: Subtotal D | D37: =SUM(D34:D36) -> 0
A38: 34 | B38: Cash deposited in bank during week
A39: 35 | B39: Cash expenditure during week
A40: 36 | B40: Sub total E | D40: =SUM(D38:D39) -> 0
...

Sheet Summary-Miriyalaguda LLP
A1: Weekly payments statement.
A2: Company:Modi Realty Miryalaguda LLP | C2: Prepared by: | D2: A.Pallavi Raja
A3: Project: | B3: AVR Gulmohar Homes | C3: Date: | D3: ='1. Bank balance statement'!B3 -> 45996
A4: S No. | B4: Weekly payments (include all payments) | C4: Cr balance | D4: Amount | E4: Pay to + VRN/CRN + Desc.
A5: 1 | B5: On a/c.
A6: 2 | B6: Hire charges on a/c.
A7: 3 | B7: Hire charges Dept.
A8: 4 | B8: Job work
A9: 5 | B9: Advance | D9: 31830 | E9: TDS for the Month of NOV'25
A10: 6 | B10: Other | D10: 21141 | E10: MHTR Trading aganist credit balances
A11: 7 | B11: Other | D11: 10125 | E11: Hoarding Rent for Nov'25
A12: 8 | B12: Other | D12: 678 | E12: MHSVC Services aganist Service charges on PO's
A13: 9 | B13: Other | D13: 495019 | E13: MPSVC-Accounts management Services,CA & CS Services for the month of NOV'25
A14: 10 | B14: Other | D14: 8640 | E14: RS Bajaj and Associates towards consultancy fees
A15: 11 | B15: Other | D15: 24737 | E15: Service Provider Bills
A16: 12 | B16: Sub-total A | D16: =SUM(D5:D15) -> 592170
A17: 13 | B17: Item | C17: Last weeks payments made after statement | D17: Payment for current week - Sat to Fri | E17: Remarks
A18: 14 | B18: Cash withdrawals | D18: 0
A19: 15 | B19: Bank/book balance | D19: 1514
A20: 16 | B20: Bank/book balance - sub total A - cash withdrawals | D20: =D19-D18-D16 -> -590656
A21: 17 | B21: Add: OD limit | D21: 0
A22: 18 | B22: Net balance available for payments - Sub-total B | D22: =SUM(D20:D21) -> -590656
A23: 19 | B23: Payments to be made for current week.
A24: 20 | B24: Suppliers bills
A25: 21 | B25: FD - cancel/make
A26: 22 | B26: Other:
A27: 23 | B27: Other:
A28: 24 | B28: Other:
A29: 25 | B29: Other:
A30: 26 | B30: Add: Payments not approved
A31: 27 | B31: Add:
A32: 28 | B32: Sub-total C | D32: =SUM(D24:D29)-D30-D31 -> 0
A33: 29 | B33: Balance: Sub-total B - C
A34: 30 | B34: Pending supplier bills (Subtotal F) | D34: 0
A35: 31 | B35: Payments received during the week. | D35: 0
A36: 32 | B36: Item | D36: Amount | E36: Remarks
A37: 33 | B37: Opening balance last week (Saturday)
A38: 34 | B38: Cash withdrawn during week
A39: 35 | B39: Cash receipts / on a/c reversal
A40: 36 | B40: Subtotal D | D40: =SUM(D37:D39) -> 0
...

Sheet 7. Inter group loans
A1: Details of secured/ unsecured loans.
A2: Prepared by:Sangeetha
A3: Date:02-05-2025
A4: Last updated on:02-05-2025
A5: Details of unsecured loans:
A6: S No. | B6: Individual/company/firm | C6: Aedis | D6: MPPL | E6: MHPL | F6: VCPL | G6: HGPL | H6: AMS
A7: 1 | B7: Villa Ordchids | C7: 10000 | E7: 0 | F7: 0
A8: 2 | E8: 0 | F8: 0
A9: 3 | E9: 0 | F9: 0
A10: 4 | E10: 0 | F10: 0
A11: 5 | E11: 0 | F11: 0
A12: 6 | E12: 0 | F12: 0
A13: 7 | E13: 0 | F13: 0
A14: 8 | E14: 0 | F14: 0
A15: 9 | E15: 0 | F15: 0
A16: 10 | E16: 0 | F16: 0
A17: 11 | E17: 0 | F17: 0
A18: 12 | E18: 0 | F18: 0
A19: 13 | E19: 0 | F19: 0
... A26: 20 | E26: 0 | F26: 0
A28: Details of secured loans:
A29: S No. | B29: Individual/company/firm | C29: Lendors name | D29: Loan approved | E29: Loan released | F29: Outstanding loan
A30: 1 | B30: NIL
A31: =A30+1 -> 2
A32: 3
A33: 4
A34: 5
A35: 6
